Traceback (most recent call last):
  File "C:\Users\great\AppData\Local\Programs\Python\Python311\Lib\site-packages\jupyter_cache\executors\utils.py", line 58, in single_nb_execution
    executenb(
  File "C:\Users\great\AppData\Local\Programs\Python\Python311\Lib\site-packages\nbclient\client.py", line 1305, in execute
    return NotebookClient(nb=nb, resources=resources, km=km, **kwargs).execute()
           ^^^^^^^^^^^^^^^^^^^^^^^^^^^^^^^^^^^^^^^^^^^^^^^^^^^^^^^^^^^^^^^^^^^^^
  File "C:\Users\great\AppData\Local\Programs\Python\Python311\Lib\site-packages\jupyter_core\utils\__init__.py", line 166, in wrapped
    return loop.run_until_complete(inner)
           ^^^^^^^^^^^^^^^^^^^^^^^^^^^^^^
  File "C:\Users\great\AppData\Local\Programs\Python\Python311\Lib\asyncio\base_events.py", line 653, in run_until_complete
    return future.result()
           ^^^^^^^^^^^^^^^
  File "C:\Users\great\AppData\Local\Programs\Python\Python311\Lib\site-packages\nbclient\client.py", line 705, in async_execute
    await self.async_execute_cell(
  File "C:\Users\great\AppData\Local\Programs\Python\Python311\Lib\site-packages\nbclient\client.py", line 1058, in async_execute_cell
    await self._check_raise_for_error(cell, cell_index, exec_reply)
  File "C:\Users\great\AppData\Local\Programs\Python\Python311\Lib\site-packages\nbclient\client.py", line 914, in _check_raise_for_error
    raise CellExecutionError.from_cell_and_msg(cell, exec_reply_content)
nbclient.exceptions.CellExecutionError: An error occurred while executing the following cell:
------------------
# NO CODE
x = np.arange(1, 26)
probs = (1/x)/sum(1/x)
dist = Table().values(x).probabilities(probs)
Plot(dist, event=np.arange(20, 26), show_ev=True)
plt.xlim(0, 25);
------------------


[1;31m---------------------------------------------------------------------------[0m
[1;31mAttributeError[0m                            Traceback (most recent call last)
Cell [1;32mIn[2], line 5[0m
[0;32m      3[0m probs [38;5;241m=[39m ([38;5;241m1[39m[38;5;241m/[39mx)[38;5;241m/[39m[38;5;28msum[39m([38;5;241m1[39m[38;5;241m/[39mx)
[0;32m      4[0m dist [38;5;241m=[39m Table()[38;5;241m.[39mvalues(x)[38;5;241m.[39mprobabilities(probs)
[1;32m----> 5[0m [43mPlot[49m[43m([49m[43mdist[49m[43m,[49m[43m [49m[43mevent[49m[38;5;241;43m=[39;49m[43mnp[49m[38;5;241;43m.[39;49m[43marange[49m[43m([49m[38;5;241;43m20[39;49m[43m,[49m[43m [49m[38;5;241;43m26[39;49m[43m)[49m[43m,[49m[43m [49m[43mshow_ev[49m[38;5;241;43m=[39;49m[38;5;28;43;01mTrue[39;49;00m[43m)[49m
[0;32m      6[0m plt[38;5;241m.[39mxlim([38;5;241m0[39m, [38;5;241m25[39m);

File [1;32m~\AppData\Local\Programs\Python\Python311\Lib\site-packages\prob140\single_variable.py:137[0m, in [0;36mPlot[1;34m(dist, width, event, edges, show_ev, show_ave, show_sd, **vargs)[0m
[0;32m    134[0m [38;5;28;01mdef[39;00m [38;5;21mprob[39m(x):
[0;32m    135[0m     [38;5;28;01mreturn[39;00m np[38;5;241m.[39marray([dist[38;5;241m.[39mprob_event(a) [38;5;28;01mfor[39;00m a [38;5;129;01min[39;00m [38;5;28mlist[39m(x)])
[1;32m--> 137[0m [38;5;28;01mif[39;00m [38;5;28misinstance[39m(event[[38;5;241m0[39m], [43mcollections[49m[38;5;241;43m.[39;49m[43mIterable[49m):
[0;32m    138[0m     [38;5;66;03m# If event is a list of lists.[39;00m
[0;32m    139[0m     colors [38;5;241m=[39m [38;5;28mlist[39m(itertools[38;5;241m.[39mislice(itertools[38;5;241m.[39mcycle(dist[38;5;241m.[39mchart_colors),
[0;32m    140[0m                                    [38;5;28mlen[39m(event) [38;5;241m+[39m [38;5;241m1[39m))
[0;32m    141[0m     [38;5;28;01mfor[39;00m i [38;5;129;01min[39;00m [38;5;28mrange[39m([38;5;28mlen[39m(event)):
[0;32m    142[0m         [38;5;66;03m# Cycle through each event and remove from the events set.[39;00m

[1;31mAttributeError[0m: module 'collections' has no attribute 'Iterable'

